Workbook
Name \__: #REF!
Name \0: #N/A
Name \a: #N/A
Name \AA: #REF!
Name \b: #N/A
Name \c: #N/A
Name \CC: #REF!
Name \d: #N/A
Name \e: #N/A
Name \f: #N/A
Name \g: #N/A
Name \h: #N/A
Name \i: #N/A
Name \j: #N/A
Name \k: #N/A
Name \KWS123: #N/A
Name \l: #REF!
Name \m: #N/A
Name \n: #N/A
Name \o: #REF!
Name \OO: #REF!
Name \P: #REF!
Name \P: #REF!
Name \q: #N/A
Name \R: #REF!
Name \s: #N/A
Name \t: #N/A
Name \U: #REF!
Name \V: #REF!
Name \X: #REF!
Name \Y: #REF!
Name \z: #N/A
Name _: #REF!
Name _: #REF!
Name ___: #REF!
Name _________________NS1: #REF!
Name ________________NS1: #REF!
Name _______________NS1: #REF!
Name ______________NS1: #REF!
Name _____________NS1: #REF!
Name ____________a1: #REF!
Name ____________NS1: #REF!
Name ___________a1: #REF!
Name ___________No1: #REF!
Name ___________No2: #REF!
Name ___________No3: #REF!
Name ___________NS1: #REF!
Name ___________sdb2: #REF!
Name __________a1: #REF!
Name __________dep123: #REF!
Name __________No1: #REF!
Name __________No2: #REF!
Name __________No3: #REF!
Name __________NS1: #REF!
Name __________sdb2: #REF!
Name _________a1: #REF!
Name _________a100: #REF!
Name _________dep123: #REF!
Name _________ETC01: #REF!
Name _________No1: #REF!

Sheet Budget
B3: MOFARREH MARZOUQ AL-HARBI & PARTNERS CO. LTD.
B5: Baseline Budget Rev. 0 EFFECTIVE BUDGET LEVLE ( 4 )
V6: *Key Legend
C7: Project name: WO# | W7: Pay Item level | Z7: Project Duration:
C8: Project No.: WO# | W8: Activity Level | Z8: Notice to proceed date:
C9: Client: | W9: Resource Level | Z9: Currency: SAR
AE10: 1e-19
A11: Item Type | B11: BOQ Item No. | C11: BOQ Description | D11: Unit | E11: Original BOQ | J11: Effective BOQ | V11: Cost Code | W11: Resources | AE11: Remaining Budget Breakdown Category
E12: Original QTY | F12: Original Selling | H12: Original Budget | J12: QTY | O12: Effective Selling | Q12: Effective Budget | W12: Res./Act. | X12: Res. Category | Y12: Res./Act. Unit | Z12: Resource Rate (SR) | AA12: Resource Productivity (MH/UNIT) | AB12: Res./Act. Budget (SR) | AC12: Res./Act. QTY | AD12: Total Cost
F13: Selling Rate | G13: Contract Amount | H13: Budget Rate | I13: Budget Amount | J13: Revised QTY | K13: Effective QTY | L13: Executed QTY upto Dec-25 | M13: Remaining QTY upto Dec-25 | N13: Remaining % | O13: Effective Selling Rate | P13: Effective Contract Amount | Q13: Effective Budget Rate | R13: ETC | S13: AC upto Dec-25 | T13: Revised Budget Amount | U13: Actual Rate | AE13: Machinery | AF13: Material | AG13: Manpower | AH13: SC | AI13: Total
C15: Total Budget | E15: 1 | G15: =G16+G35 -> 2.3377608e+08 | I15: =I16+I35 -> 1.5820276e+08 | P15: =P16+P35 -> 2.3377608e+08 | R15: =R16+R35 -> 1.5820276e+08 | S15: =S16+S35 -> 0 | T15: =T16+T35 -> 1.5820276e+08
C16: Indirect Budget | E16: 1 | G16: =SUM(G17:G34) -> 0 | I16: =SUM(I17:I34) -> 37202527 | P16: =SUM(P17:P34) -> 0 | R16: =SUM(R17:R34) -> 37202527 | S16: =SUM(S17:S34) -> 0 | T16: =SUM(T17:T34) -> 37202527
B17: IND01 | C17: Indirect Labour Cost | D17: Ea | E17: 1 | H17: 19627660 | I17: =H17*E17 -> 19627660 | J17: =E17 -> 1 | K17: =E17 -> 1 | M17: =K17-L17 -> 1 | Q17: 19627660 | R17: =M17*Q17 -> 19627660 | T17: =S17+R17 -> 19627660
B18: IND02 | C18: Staff Cars | D18: Ea | E18: 1 | H18: 2192647 | I18: =H18*E18 -> 2192647 | J18: =E18 -> 1 | K18: =E18 -> 1 | M18: =K18-L18 -> 1 | Q18: 2192647 | R18: =M18*Q18 -> 2192647 | T18: =S18+R18 -> 2192647
B19: IND03 | C19: Fuel for Staff Cars | D19: Ea | E19: 1 | H19: 593611.5 | I19: =H19*E19 -> 593611.5 | J19: =E19 -> 1 | K19: =E19 -> 1 | M19: =K19-L19 -> 1 | Q19: 593611.5 | R19: =M19*Q19 -> 593611.5 | T19: =S19+R19 -> 593611.5
B20: IND04 | C20: Indirect Equipment Cost | D20: Ea | E20: 1 | H20: 2736630 | I20: =H20*E20 -> 2736630 | J20: =E20 -> 1 | K20: =E20 -> 1 | M20: =K20-L20 -> 1 | Q20: 2736630 | R20: =M20*Q20 -> 2736630 | T20: =S20+R20 -> 2736630
B21: IND05 | C21: Fuel for Indirect Equip. | D21: Ea | E21: 1 | H21: 1262384.5 | I21: =H21*E21 -> 1262384.5 | J21: =E21 -> 1 | K21: =E21 -> 1 | M21: =K21-L21 -> 1 | O21: =F21 -> 0 | P21: =K21*O21 -> 0 | Q21: 1262384.5 | R21: =M21*Q21 -> 1262384.5 | T21: =S21+R21 -> 1262384.5
B22: IND06 | C22: Camp Cost (Food and Accommodation) | D22: Ea | E22: 1 | H22: 4174002 | I22: =H22*E22 -> 4174002 | J22: =E22 -> 1 | K22: =E22 -> 1 | M22: =K22-L22 -> 1 | Q22: 4174002 | R22: =M22*Q22 -> 4174002 | T22: =S22+R22 -> 4174002
B23: IND07 | C23: Mobilization | D23: Ea | E23: 1 | H23: 546000 | I23: =H23*E23 -> 546000 | J23: =E23 -> 1 | K23: =E23 -> 1 | M23: =K23-L23 -> 1 | Q23: 546000 | R23: =M23*Q23 -> 546000 | T23: =S23+R23 -> 546000
B24: IND08 | C24: Demobilization | D24: Ea | E24: 1 | H24: 54600 | I24: =H24*E24 -> 54600 | J24: =E24 -> 1 | K24: =E24 -> 1 | M24: =K24-L24 -> 1 | Q24: 54600 | R24: =M24*Q24 -> 54600 | T24: =S24+R24 -> 54600
B25: IND09 | C25: General Tools | D25: Ea | E25: 1 | H25: 108100 | I25: =H25*E25 -> 108100 | J25: =E25 -> 1 | K25: =E25 -> 1 | M25: =K25-L25 -> 1 | Q25: 108100 | R25: =M25*Q25 -> 108100 | T25: =S25+R25 -> 108100
B26: IND10 | C26: Project Running Cost | D26: Ea | E26: 1 | H26: 519000 | I26: =H26*E26 -> 519000 | J26: =E26 -> 1 | K26: =E26 -> 1 | M26: =K26-L26 -> 1 | Q26: 519000 | R26: =M26*Q26 -> 519000 | T26: =S26+R26 -> 519000
B27: IND11 | C27: Waste Management | D27: Ea | E27: 1 | H27: 893600 | I27: =H27*E27 -> 893600 | J27: =E27 -> 1 | K27: =E27 -> 1 | M27: =K27-L27 -> 1 | Q27: 893600 | R27: =M27*Q27 -> 893600 | T27: =S27+R27 -> 893600
B28: IND12 | C28: Safety, Medical & Traffic Control | D28: Ea | E28: 1 | H28: 514091 | I28: =H28*E28 -> 514091 | J28: =E28 -> 1 | K28: =E28 -> 1 | M28: =K28-L28 -> 1 | Q28: 514091 | R28: =M28*Q28 -> 514091 | T28: =S28+R28 -> 514091
B29: IND13 | C29: Lab Testing & Project Services | D29: Ea | E29: 1 | H29: 288000 | I29: =H29*E29 -> 288000 | J29: =E29 -> 1 | K29: =E29 -> 1 | M29: =K29-L29 -> 1 | Q29: 288000 | R29: =M29*Q29 -> 288000 | T29: =S29+R29 -> 288000
B30: IND14 | C30: Survey Expenses | D30: Ea | E30: 1 | H30: 50000 | I30: =H30*E30 -> 50000 | J30: =E30 -> 1 | K30: =E30 -> 1 | M30: =K30-L30 -> 1 | Q30: 50000 | R30: =M30*Q30 -> 50000 | T30: =S30+R30 -> 50000
B31: IND15 | C31: Security Expenses | D31: Ea | E31: 1 | H31: 720000 | I31: =H31*E31 -> 720000 | J31: =E31 -> 1 | K31: =E31 -> 1 | M31: =K31-L31 -> 1 | Q31: 720000 | R31: =M31*Q31 -> 720000 | T31: =S31+R31 -> 720000
B32: IND16 | C32: Design Services | D32: Ea | E32: 1 | H32: 0 | I32: =H32*E32 -> 0 | J32: =E32 -> 1 | K32: =E32 -> 1 | M32: =K32-L32 -> 1 | Q32: 0 | R32: =M32*Q32 -> 0 | T32: =S32+R32 -> 0
B33: IND17 | C33: Warrantee Period Maintenance Cost | D33: Ea | E33: 1 | H33: 584440.19 | I33: =H33*E33 -> 584440.19 | J33: =E33 -> 1 | K33: =E33 -> 1 | M33: =K33-L33 -> 1 | Q33: 584440.19 | R33: =M33*Q33 -> 584440.19 | T33: =S33+R33 -> 584440.19
B34: IND18 | C34: Program Overhead | D34: Ea | E34: 1 | H34: 2337760.8 | I34: =H34*E34 -> 2337760.8 | J34: =E34 -> 1 | K34: =E34 -> 1 | M34: =K34-L34 -> 1 | Q34: 2337760.8 | R34: =M34*Q34 -> 2337760.8 | T34: =S34+R34 -> 2337760.8
C35: Direct Budget | G35: =+SUMIF($AK:$AK,"5",G:G) -> 2.3377608e+08 | I35: =+SUMIF($AK:$AK,"5",I:I) -> 1.2100023e+08 | P35: =+SUMIF($AK:$AK,"5",P:P) -> 2.3377608e+08 | R35: =+SUMIF($AK:$AK,"5",R:R) -> 1.2100023e+08 | S35: =+SUMIF($AK:$AK,"5",S:S) -> 0 | T35: =+SUMIF($AK:$AK,"5",T:T) -> 1.2100023e+08 | AD35: =+SUMIF($AK:$AK,"5",AD:AD) -> 1.2100023e+08 | AE35: =SUMIF($AK:$AK,5,AE:AE) -> 219500 | AF35: =SUMIF($AK:$AK,5,AF:AF) -> 219500 | AG35: =SUMIF($AK:$AK,5,AG:AG) -> 219500 | AH35: =SUMIF($AK:$AK,5,AH:AH) -> 219500 | AI35: =SUMIF($AK:$AK,5,AI:AI) -> 878000
A37: General items | B37: 1 | C37: Preparing, installing and setting up site offices | D37: sum | E37: 0.1 | F37: 617230 | G37: =F37*E37 -> 61723 | H37: =AB37 -> 925000 | I37: =H37*E37 -> 92500 | J37: =E37 -> 0.1 | K37: =J37 -> 0.1 | M37: =K37-L37 -> 0.1 | N37: =IFERROR(M37/K37,0) -> 1 | O37: =F37 -> 617230 | P37: =K37*O37 -> 61723 | Q37: =AB37 -> 925000 | R37: =M37*Q37 -> 92500 | T37: =S37+R37 -> 92500 | AB37: =AD37/AC37 -> 925000 | AC37: =M37+$AE$10 -> 0.1 | AD37: =AD38 -> 92500 | AE37: =AE38 -> 0 | AF37: =AF38 -> 0 | AG37: =AG38 -> 0 | AH37: =AH38 -> 0 | AI37: =SUM(AE37:AH37) -> 0 | AK37: 5 | AO37: Original Pay item
J38: =J37 -> 0.1 | K38: =K37 -> 0.1 | M38: =K38-L38 -> 0.1 | W38: Setting up site offices (Remining Works) | Y38: LS | Z38: =AD38/AC38 -> 925000 | AB38: =AD38/AC38 -> 925000 | AC38: =M38+$AE$10 -> 0.1 | AD38: =SUM(AD39:AD45) -> 92500 | AE38: =SUMIFS($AD$37:$AD$12971,$V$37:$V$12971,$V38,$X$37:$X$12971,AE$13) -> 0 | AF38: =SUMIFS($AD$37:$AD$12971,$V$37:$V$12971,$V38,$X$37:$X$12971,AF$13) -> 0 | AG38: =SUMIFS($AD$37:$AD$12971,$V$37:$V$12971,$V38,$X$37:$X$12971,AG$13) -> 0 | AH38: =SUMIFS($AD$37:$AD$12971,$V$37:$V$12971,$V38,$X$37:$X$12971,AH$13) -> 0 | AI38: =SUM(AE38:AH38) -> 0
W39: Supply and applying Electric connections | X39: SC | Y39: LS | Z39: =VLOOKUP(W39,Sheet2!$B:$D,3,FALSE) -> 25000 | AA39: =1/10 -> 0.1 | AB39: =AD39/AC38 -> 250000 | AC39: =AC38/AA39 -> 1 | AD39: =AC39*Z39 -> 25000
W40: Supply and applying Mechnical connections | X40: SC | Y40: LS | Z40: =VLOOKUP(W40,Sheet2!$B:$D,3,FALSE) -> 35000 | AA40: 0.1 | AB40: =AD40/AC38 -> 350000 | AC40: =AC38/AA40 -> 1 | AD40: =AC40*Z40 -> 35000
W41: Supply and Apply Plants with the Soil Mix | X41: SC | Y41: LS | Z41: =VLOOKUP(W41,Sheet2!$B:$D,3,FALSE) -> 10000 | AA41: 0.1 | AB41: =AD41/AC38 -> 100000 | AC41: =AC38/AA41 -> 1 | AD41: =AC41*Z41 -> 10000
W42: Supply AC Unit | X42: Material | Y42: LS | Z42: =VLOOKUP(W42,Sheet2!$B:$D,3,FALSE) -> 13000 | AA42: 0.1 | AB42: =AD42/AC38 -> 130000 | AC42: =AC38/AA42 -> 1 | AD42: =AC42*Z42 -> 13000
W43: Supply cabines Doors | X43: Material | Y43: LS | Z43: =VLOOKUP(W43,Sheet2!$B:$D,3,FALSE) -> 6500 | AA43: 0.1 | AB43: =AD43/AC38 -> 65000 | AC43: =AC38/AA43 -> 1 | AD43: =AC43*Z43 -> 6500
W44: Skilled Labor | X44: Manpower | Y44: HR | Z44: =VLOOKUP(W44,Sheet2!$B:$D,3,FALSE) -> 17 | AA44: 0.001 | AB44: =AD44/AC38 -> 17000 | AC44: =AC38/AA44 -> 100 | AD44: =AC44*Z44 -> 1700
W45: Unskilled Labour | X45: Manpower | Y45: HR | Z45: =VLOOKUP(W45,Sheet2!$B:$D,3,FALSE) -> 13 | AA45: 0.001 | AB45: =AD45/AC38 -> 13000 | AC45: =AC38/AA45 -> 100 | AD45: =AC45*Z45 -> 1300
...

Sheet Sheet2
B3: Resources | C3: UOM | D3: Rate | E3: Type
B4: Fuel | C4: Ltre | D4: 1.76
B5: Unskilled Labour | C5: HR | D5: 13
B6: Skilled Labor | C6: HR | D6: 17
B7: Bulldozer CAT D9 | C7: HR | D7: 132.304
B8: Bulldozer CAT D8 | C8: HR | D8: 111.568
B9: Bulldozer CAT D4 | C9: HR | D9: 105
B10: Wheel Excavator 20T With Bucket/Hock | C10: HR | D10: 68
B11: Excavator with Bucket 20T | C11: HR | D11: 56
B12: Excavator with Hydraulic Hammer 20T | C12: HR | D12: 58.4
B13: Excavator with Bucket 50T | C13: HR | D13: 131.2
B14: Excavator with Hydraulic Hammer 50T | C14: HR | D14: 150.4
B15: Excavator 75T with Bucket | C15: HR | D15: 236
... B127: Non-woven Geotextile Installation | C127: M² | D127: 0.9
B128: Orange warning Mesh | C128: M² | D128: =30/50 -> 0.6
B131: 125 mm solid HDPE Pipe DR 11 | C131: M | D131: 35
B132: 160 mm solid HDPE Pipe DR 11 | C132: M | D132: 39
B133: 200 mm solid HDPE Pipe DR 11 | C133: M | D133: 50
B134: 225 mm solid HDPE Pipe DR 11 | C134: M | D134: 75
B135: 250 mm solid HDPE Pipe DR 11 | C135: M | D135: 95
B136: 280 mm solid HDPE Pipe DR 11 | C136: M | D136: 110
B137: 315 mm solid HDPE Pipe DR 11 | C137: M | D137: 145
B138: 355 mm solid HDPE Pipe DR 11 | C138: M | D138: 190
B139: 400 mm solid HDPE Pipe DR 11 | C139: M | D139: 229.9
B140: 500 mm solid HDPE Pipe DR 11 | C140: M | D140: 345
B141: 560 mm solid HDPE Pipe DR 11 | C141: M | D141: 510
B142: 630 mm solid HDPE Pipe DR 11 | C142: M | D142: 610
... B149: 250 mm HDPE Pipe Installation | C149: M | D149: 30
B150: 280 mm HDPE Pipe Installation | C150: M | D150: 33 | H150: 160 mm HDPE Fittings & Accessories | I150: M | J150: 25
B151: 315 mm HDPE Pipe Installation | C151: M | D151: 38 | H151: 200 mm HDPE Fittings & Accessories | I151: M | J151: 30
B152: 355 mm HDPE Pipe Installation | C152: M | D152: 44 | H152: 315 mm HDPE Fittings & Accessories | I152: M | J152: 130
B153: 400 mm HDPE Pipe Installation | C153: M | D153: 50 | H153: 400 mm HDPE Fittings & Accessories | I153: M | J153: 180
B154: 500 mm HDPE Pipe Installation | C154: M | D154: 55 | H154: 630 mm HDPE Fittings & Accessories | I154: M | J154: 250
B155: 560 mm HDPE Pipe Installation | C155: M | D155: 60
B156: 630 mm HDPE Pipe Installation | C156: M | D156: 60
B157: 710 mm HDPE Pipe Installation | C157: M | D157: 120
B159: Supply Elbow 11.5°, diameter 125mm | C159: Ea | D159: 205
B160: Supply Elbow 45°, diameter 125mm | C160: Ea | D160: 215
B161: Supply Elbow 90°, diameter 125mm | C161: Ea | D161: 227.5
B162: Supply Elbow 11.5°, diameter 160mm | C162: Ea | D162: 224.5
...

Sheet Level 3
C1: PAY ITEM No. (Refer Attach "D" Article 2-03) | D1: DESCRIPTION OF ITEMS | E1: Budget Amount | H1: Subcontractor | I1: Material | J1: Manpower | K1: Machinery
A2: ENVIRONMENTAL WORKS | B2: STORM DRAINAGE NETWORK | D2: Direct Budget | E2: =Budget!T35 -> 1.2100023e+08
A3: ENVIRONMENTAL WORKS | B3: STORM DRAINAGE NETWORK | D3: Material | E3: =+Budget!AF35 -> 219500
A4: ENVIRONMENTAL WORKS | B4: STORM DRAINAGE NETWORK | C4: 15.4 | D4: Manpower | E4: =+Budget!AG35 -> 219500
A5: ENVIRONMENTAL WORKS | B5: STORM DRAINAGE NETWORK | C5: 15.4.1 | D5: Machinery | E5: =+Budget!AE35 -> 219500 | H5: =SUMIF(#REF!,$H$1,#REF!) -> #REF! | I5: =SUMIF(#REF!,$I$1,#REF!) -> #REF! | J5: =SUMIF(#REF!,$J$1,#REF!) -> #REF! | K5: =SUMIF(#REF!,$K$1,#REF!) -> #REF! | L5: =+#REF!-H5-I5-J5-K5 -> #REF!
A6: ENVIRONMENTAL WORKS | B6: STORM DRAINAGE NETWORK | D6: Subcontractor | E6: =+Budget!AH35 -> 219500
H7: 1658389.6 | I7: 16442314 | J7: 2825018.1 | K7: 5795428.4
A8: ENVIRONMENTAL WORKS | B8: STORM DRAINAGE NETWORK | D8: Indirect Budget | E8: =Budget!T16 -> 37202527
A10: ENVIRONMENTAL WORKS | B10: STORM DRAINAGE NETWORK | D10: Total Project Budget | E10: =+E2+E8 -> 1.5820276e+08

Sheet Summary
C1: overall BUDGET Summary
B2: PROJECT NAME: | C2: MODON 3rd Industrial City Phase 1D – Part 2 – Dammam | D2: REV. DATE.: | E2: 45874
B3: SITE LOCATION: | C3: Eastern Region | D3: REV. NO.: | E3: 0
B4: START DATE: | C4: 45778 | D4: PROJECT CODE: | E4: S1-CNS-EP-MOD-2025.3
B5: DURATION: | C5: 16 MTH | D5: CONTRACT PRICE : | E5: 2.3377608e+08
B6: FINISH DATE: | C6: 46538 | D6: BU Number: | E6: 0
B7: REV. FINISH DATE: | C7: 0
B11: No. | C11: Description | D11: Budget | E11: Remark
B12: 1 | C12: Direct Cost | D12: =Budget!I35 -> 1.2100023e+08
B13: =B12+1 -> 2 | C13: Indirect Cost | D13: =Budget!I16 -> 37202527
B14: =B13+1 -> 3 | C14: Contingency Reserve | D14: =E14*E5 -> 23377608 | E14: 0.1
C15: Total Amount | D15: =SUM(D12:D14) -> 1.8158037e+08
C17: Items | D17: Amount | E17: %
B18: A | C18: Contract Price | D18: =E5 -> 2.3377608e+08 | E18: =IFERROR(D18/$E$5,0) -> 1
B19: B | C19: Direct Cost | D19: =-D12 -> -1.2100023e+08 | E19: =-D19/$D$18 -> 0.51759031
B20: C | C20: Indirect Cost | D20: =-D13 -> -37202527 | E20: =-D20/$D$18 -> 0.15913744
B21: D | C21: Contingency Reserve | D21: =-D14 -> -23377608 | E21: =-D21/$D$18 -> 0.1
B22: E= (B+C+D) | C22: Sub-Total | D22: =SUM(D19:D21) -> -1.8158037e+08 | E22: =-D22/$D$18 -> 0.77672775
B23: F=(A+E) | C23: Gross Margin | D23: =D18+D22 -> 52195710 | E23: =D23/$E$5 -> 0.22327225
B24: G | C24: Advance Payment Fees | D24: =-E5*10%*0.75%*2*0.5 -> -175332.06 | E24: =-D24/E5 -> 0.00075
B25: H | C25: Performance Bond Fees | D25: -70017 | E25: =-D25/E5 -> 0.00029950456
B26: I | C26: LC Fees | D26: 0 | E26: =-D26/E5 -> 0
B27: J | C27: CAR Insurance | D27: -338506.86 | E27: =-D27/E5 -> 0.0014479962
B28: K | C28: Management Reserve | D28: =-(E28*E5) -> -1168880.4 | E28: 0.005
B29: L | C29: General and Administrative Expenses (G&A) | D29: =-E29*E5 -> -11688804 | E29: 0.05
B30: K=(F+G+H+I+J+K+L) | C30: Net Profit Margin | D30: =D23+D24+D25+D26+D27+D28+D29 -> 38754170 | E30: =D30/$E$5 -> 0.16577475
